Workbook

Sheet Свод цен
A1: ГАЗЛИ–НУКУС 1 — СВОДНЫЙ ПЕРЕЧЕНЬ ЦЕН РЕСУРСОВ
A2: Строительство лупинга МГ «Газли–Нукус» I-нитка. Источник: локальные ресурсные сметы № 1-1 (Линейная часть), 1-2 (ЭХЗ), 1-3 (Внешнее электроснабжение 6 кВ средств УКЗ), 1-4 (АС). Цены в текущих ценах, сум. По каждому ресурсу — максимальная цена из 4 ЛРС.
A4: № | B4: Раздел | C4: Наименование ресурса | D4: Ед. изм. | E4: Цена за ед., сум (макс.) | F4: Цена мин., сум | G4: Кол-во разных цен | H4: Где встречается | I4: Примечание
A5: ЗАТРАТЫ ТРУДА
A6: 1 | B6: Затраты труда | C6: ДОП.ПЕРЕМЕЩЕНИЕ МАШИНИСТОВ ПО ТРАССЕ ДО МЕСТА РАБОТЫ | D6: ЧЕЛ.-Ч | G6: 0 | H6: 1-1, 1-2 | I6: оплата машинистов учтена в стоимости маш-ч
A7: 2 | B7: Затраты труда | C7: ДОП.ПЕРЕМЕЩЕНИЕ РАБОЧИХ-СТРОИТЕЛЕЙ ПО ТРАССЕ ДО МЕСТА РАБОТЫ | D7: ЧЕЛ.-Ч | E7: 25287.349 | F7: 25287.349 | G7: 1 | H7: 1-1, 1-2 | I7: цена из строки «Итого по трудовым ресурсам»
A8: 3 | B8: Затраты труда | C8: ЗАТРАТЫ ТРУДА МАШИНИСТОВ | D8: ЧЕЛ.-Ч | G8: 0 | H8: 1-1, 1-2, 1-3, 1-4 | I8: оплата машинистов учтена в стоимости маш-ч
A9: 4 | B9: Затраты труда | C9: ЗАТРАТЫ ТРУДА РАБОЧИХ МОНТАЖНИКОВ | D9: ЧЕЛ.-Ч | E9: 25287.349 | F9: 25287.349 | G9: 1 | H9: 1-2 | I9: цена из строки «Итого по трудовым ресурсам»
A10: 5 | B10: Затраты труда | C10: ЗАТРАТЫ ТРУДА РАБОЧИХ-СТРОИТЕЛЕЙ | D10: ЧЕЛ.-Ч | E10: 25287.349 | F10: 25287.349 | G10: 1 | H10: 1-1, 1-2, 1-3, 1-4 | I10: цена из строки «Итого по трудовым ресурсам»
A11: МАШИНЫ И МЕХАНИЗМЫ
A12: 6 | B12: Машины и механизмы | C12: АВТОГИДРОПОДЪЕМНИКИ ВЫСОТОЙ ПОДЪЕМА 12 М | D12: МАШ.-Ч | E12: 118630 | F12: 118630 | G12: 1 | H12: 1-2, 1-3
A13: 7 | B13: Машины и механизмы | C13: АВТОГРЕЙДЕР "КАМАЦУ" 149 КВТ (200 Л.С.) | D13: МАШ.-Ч | E13: 225000 | F13: 225000 | G13: 1 | H13: 1-2
A14: 8 | B14: Машины и механизмы | C14: АВТОГРЕЙДЕРЫ СРЕДНЕГО ТИПА 99 (135) КВТ (Л.С.) | D14: МАШ.-Ч | E14: 407372.3 | F14: 407372.3 | G14: 1 | H14: 1-1, 1-2, 1-4
A15: 9 | B15: Машины и механизмы | C15: АВТОКРАН МАРКИ ХZJ5556QZ100К ГРУЗОПОДЪЕМНОСТЬЮ 100 ТОНН | D15: МАШ.Ч | E15: 733894.48 | F15: 733894.48 | G15: 1 | H15: 1-4
A16: 10 | B16: Машины и механизмы | C16: АВТОМАТЫ СВАРОЧНЫЕ С НОМИНАЛЬНЫМ СВАРОЧНЫМ ТОКОМ 450-1250 А | D16: МАШ.-Ч | E16: 27770 | F16: 27770 | G16: 1 | H16: 1-2
A17: 11 | B17: Машины и механизмы | C17: АВТОМОБИЛИ БОРТОВЫЕ ГРУЗОПОДЪЕМНОСТЬЮ ДО 5 Т | D17: МАШ.-Ч | E17: 428434.3 | F17: 428434.3 | G17: 1 | H17: 1-1, 1-2, 1-3, 1-4
A18: 12 | B18: Машины и механизмы | C18: АВТОМОБИЛИ БОРТОВЫЕ ГРУЗОПОДЪЕМНОСТЬЮ ДО 8 Т | D18: МАШ.-Ч | E18: 495524.27 | F18: 495524.27 | G18: 1 | H18: 1-2, 1-3, 1-4
A19: 13 | B19: Машины и механизмы | C19: АВТОМОБИЛИ-САМОСВАЛЫ ГРУЗОПОДЪЕМНОСТЬЮ ДО 10 Т | D19: МАШ.-Ч | E19: 495524 | F19: 495524 | G19: 1 | H19: 1-1, 1-2, 1-4
A20: 14 | B20: Машины и механизмы | C20: АВТОМОБИЛИ-САМОСВАЛЫ ГРУЗОПОДЪЕМНОСТЬЮ ДО 7 Т | D20: МАШ.-Ч | E20: 140361 | F20: 140361 | G20: 1 | H20: 1-2, 1-4
A21: 15 | B21: Машины и механизмы | C21: АВТОПОГРУЗЧИКИ 5 Т | D21: МАШ.-Ч | E21: 143063 | F21: 143063 | G21: 1 | H21: 1-1, 1-2, 1-4
A22: 16 | B22: Машины и механизмы | C22: АВТОЦЕМЕНТОВОЗЫ 13 Т | D22: МАШ.-Ч | E22: 125710.66 | F22: 125710.66 | G22: 1 | H22: 1-2
A23: 17 | B23: Машины и механизмы | C23: АВТОЦИСТЕРНА, ОБЪЕМ ВОДЫ 8 М3 | D23: МАШ.-Ч | E23: 133766 | F23: 133766 | G23: 1 | H23: 1-2
... A33: 27 | B33: Машины и механизмы | C33: АППАРАТЫ ДЛЯ ГАЗОВОЙ СВАРКИ И РЕЗКИ | D33: МАШ.-Ч | E33: 23251 | F33: 23251 | G33: 1 | H33: 1-1, 1-2, 1-4
A34: 28 | B34: Машины и механизмы | C34: АППАРАТЫ ДРОБЕСТРУЙНЫЕ ПНЕВМАТИЧЕСКИЕ | D34: МАШ.-Ч | G34: 0 | H34: 1-1 | I34: цена в ЛРС не указана
A35: 29 | B35: Машины и механизмы | C35: АППАРАТЫ РЕНТГЕНО-ДЕФЕКТОСКОПИЧЕСКИЕ С ТОЛЩИНОЙ ПРОСВЕЧИВАЕМОЙ СТАЛИ ДО 25 ММ | D35: МАШ.-Ч | E35: 959.8 | F35: 959.8 | G35: 1 | H35: 1-1
A36: 30 | B36: Машины и механизмы | C36: БУЛЬДОЗЕР Т-140 МОЩНОСТЬЮ 102 (140) КВТ (Л.С.) | D36: МАШ.-Ч | E36: 141420.54 | F36: 141420.54 | G36: 1 | H36: 1-4
A37: 31 | B37: Машины и механизмы | C37: БУЛЬДОЗЕРЫ SНАNТUI SD32 МОЩНОСТЬЮ 235 (320) КВТ (Л.С.) | D37: МАШ.-Ч | E37: 665973.48 | F37: 665973.48 | G37: 1 | H37: 1-4
A38: 32 | B38: Машины и механизмы | C38: БУЛЬДОЗЕРЫ ПРИ РАБОТЕ НА ГИДРОЭНЕРГЕТИЧЕСКОМ СТРОИТЕЛЬСТВЕ И ГОРНОВСКРЫШНЫХ РАБОТАХ 79 (108) КВТ (Л.С.) | D38: МАШ.-Ч | E38: 628141.12 | F38: 628141.12 | G38: 1 | H38: 1-4
A39: 33 | B39: Машины и механизмы | C39: БУЛЬДОЗЕРЫ ПРИ РАБОТЕ НА ГИДРОЭНЕРГЕТИЧЕСКОМ СТРОИТЕЛЬСТВЕ И ГОРНОВСКРЫШНЫХ РАБОТАХ ДО 59 (80) КВТ (Л.С.) | D39: МАШ.-Ч | G39: 0 | H39: 1-4 | I39: цена в ЛРС не указана
A40: 34 | B40: Машины и механизмы | C40: БУЛЬДОЗЕРЫ ПРИ РАБОТЕ НА ДРУГИХ ВИДАХ СТРОИТЕЛЬСТВА (КРОМЕ ВОДОХОЗЯЙСТВЕННОГО) 132 (180) КВТ (Л.С.) | D40: МАШ.-Ч | E40: 665973.48 | F40: 665973.48 | G40: 1 | H40: 1-1
A41: 35 | B41: Машины и механизмы | C41: БУЛЬДОЗЕРЫ ПРИ РАБОТЕ НА ДРУГИХ ВИДАХ СТРОИТЕЛЬСТВА (КРОМЕ ВОДОХОЗЯЙСТВЕННОГО) 96 (130) КВТ (Л.С.) | D41: МАШ.-Ч | E41: 361374.45 | F41: 361374.45 | G41: 1 | H41: 1-2
A42: 36 | B42: Машины и механизмы | C42: БУЛЬДОЗЕРЫ ПРИ РАБОТЕ НА ДРУГИХ ВИДАХ СТРОИТЕЛЬСТВА 79 (108) КВТ (Л.С.) | D42: МАШ.-Ч | E42: 628141.12 | F42: 628141.12 | G42: 1 | H42: 1-1, 1-2, 1-4
A43: 37 | B43: Машины и механизмы | C43: БУЛЬДОЗЕРЫ ПРИ РАБОТЕ НА СООРУЖЕНИИ МАГИСТРАЛЬНЫХ ТРУБОПРОВОДОВ 121 (165) КВТ (Л.С.) | D43: МАШ.-Ч | E43: 665973.48 | F43: 665973.48 | G43: 1 | H43: 1-1
A44: 38 | B44: Машины и механизмы | C44: БУЛЬДОЗЕРЫ ПРИ РАБОТЕ НА СООРУЖЕНИИ МАГИСТРАЛЬНЫХ ТРУБОПРОВОДОВ 96 (130) КВТ (Л.С.) | D44: МАШ.-Ч | E44: 628141.12 | F44: 628141.12 | G44: 1 | H44: 1-1
A45: 39 | B45: Машины и механизмы | C45: БУЛЬДОЗЕРЫ ПРИ РАБОТЕ НА СООРУЖЕНИИ МАГИСТРАЛЬНЫХ ТРУБОПРОВОДОВ ДО 59 (80) КВТ (Л.С.) | D45: МАШ.-Ч | E45: 628141.12 | F45: 628141.12 | G45: 1 | H45: 1-1
A46: 40 | B46: Машины и механизмы | C46: БУНКЕРЫ | D46: МАШ.-Ч | E46: 3295.33 | F46: 3295.33 | G46: 1 | H46: 1-4
A47: 41 | B47: Машины и механизмы | C47: ВИБРАТОРЫ ГЛУБИННЫЕ | D47: МАШ.-Ч | E47: 67125 | F47: 67125 | G47: 1 | H47: 1-2, 1-4
A48: 42 | B48: Машины и механизмы | C48: ВИБРОПЛИТА СVР 110 | D48: МАШ.-Ч | E48: 125000 | F48: 125000 | G48: 1 | H48: 1-4
A49: 43 | B49: Машины и механизмы | C49: ВЫПРЯМИТЕЛИ СВАРОЧНЫЕ ЛИЕКОЛН ДС-400 | D49: МАШ.-Ч | E49: 330196 | F49: 330196 | G49: 1 | H49: 1-1
A50: 44 | B50: Машины и механизмы | C50: ВЫШКИ ТЕЛЕСКОПИЧЕСКИЕ 25 М | D50: МАШ.-Ч | E50: 142421 | F50: 142421 | G50: 1 | H50: 1-3
...

Sheet Все ресурсы
A1: ГАЗЛИ–НУКУС 1 — ВСЕ РЕСУРСЫ ПО ЛРС
A2: Строительство лупинга МГ «Газли–Нукус» I-нитка. Источник: локальные ресурсные сметы № 1-1 (Линейная часть), 1-2 (ЭХЗ), 1-3 (Внешнее электроснабжение 6 кВ средств УКЗ), 1-4 (АС). Цены в текущих ценах, сум.
A4: ЛРС | B4: Часть | C4: Раздел | D4: № в ЛРС | E4: Наименование ресурса | F4: Ед. изм. | G4: Количество | H4: Цена за ед., сум | I4: Сумма, сум | J4: Стр. в исходном файле | K4: Примечание
A5: ЛРС № 1-1 | B5: Линейная часть | C5: Затраты труда | D5: 1 | E5: ЗАТРАТЫ ТРУДА РАБОЧИХ-СТРОИТЕЛЕЙ | F5: ЧЕЛ.-Ч | G5: 72164.73 | H5: 25287.349 | J5: 19 | K5: цена из строки «Итого по трудовым ресурсам»
A6: ЛРС № 1-1 | B6: Линейная часть | C6: Затраты труда | D6: 2 | E6: ЗАТРАТЫ ТРУДА МАШИНИСТОВ | F6: ЧЕЛ.-Ч | G6: 54806.818 | J6: 20 | K6: оплата машинистов учтена в стоимости маш-ч
A7: ЛРС № 1-1 | B7: Линейная часть | C7: Затраты труда | D7: 3 | E7: ДОП.ПЕРЕМЕЩЕНИЕ РАБОЧИХ-СТРОИТЕЛЕЙ ПО ТРАССЕ ДО МЕСТА РАБОТЫ | F7: ЧЕЛ.-Ч | G7: 5487.5097 | H7: 25287.349 | J7: 21 | K7: цена из строки «Итого по трудовым ресурсам»
A8: ЛРС № 1-1 | B8: Линейная часть | C8: Затраты труда | D8: 4 | E8: ДОП.ПЕРЕМЕЩЕНИЕ МАШИНИСТОВ ПО ТРАССЕ ДО МЕСТА РАБОТЫ | F8: ЧЕЛ.-Ч | G8: 5248.2777 | J8: 22 | K8: оплата машинистов учтена в стоимости маш-ч
A9: ЛРС № 1-1 | B9: Линейная часть | C9: Машины и механизмы | D9: 1 | E9: АВТОГРЕЙДЕРЫ СРЕДНЕГО ТИПА 99 (135) КВТ (Л.С.) | F9: МАШ.-Ч | G9: 0.4416 | H9: 407372.3 | I9: 179895.61 | J9: 26
A10: ЛРС № 1-1 | B10: Линейная часть | C10: Машины и механизмы | D10: 2 | E10: АВТОПОГРУЗЧИКИ 5 Т | F10: МАШ.-Ч | G10: 81.5208 | H10: 143063 | I10: 11662610 | J10: 27
A11: ЛРС № 1-1 | B11: Линейная часть | C11: Машины и механизмы | D11: 3 | E11: АГРЕГАТЫ СВАРОЧНЫЕ ДВУХПОСТОВЫЕ ДЛЯ РУЧНОЙ СВАРКИ НА ТРАКТОРЕ 79 КВТ (108 Л.С.) | F11: МАШ.-Ч | G11: 1728.1651 | H11: 456905.21 | I11: 7.8960765e+08 | J11: 28
A12: ЛРС № 1-1 | B12: Линейная часть | C12: Машины и механизмы | D12: 4 | E12: АГРЕГАТЫ СВАРОЧНЫЕ ПЕРЕДВИЖНЫЕ С НОМИНАЛЬНЫМ СВАРОЧНЫМ ТОКОМ 250-400 А С ДИЗЕЛЬНЫМ ДВИГАТЕЛЕМ | F12: МАШ.-Ч | G12: 25.7607 | H12: 111320 | I12: 2867681.1 | J12: 29
A13: ЛРС № 1-1 | B13: Линейная часть | C13: Машины и механизмы | D13: 5 | E13: АППАРАТЫ РЕНТГЕНО-ДЕФЕКТОСКОПИЧЕСКИЕ С ТОЛЩИНОЙ ПРОСВЕЧИВАЕМОЙ СТАЛИ ДО 25 ММ | F13: МАШ.-Ч | G13: 1267.7 | H13: 959.8 | I13: 1216738.5 | J13: 30
A14: ЛРС № 1-1 | B14: Линейная часть | C14: Машины и механизмы | D14: 6 | E14: АВТОМОБИЛИ-САМОСВАЛЫ ГРУЗОПОДЪЕМНОСТЬЮ ДО 10 Т | F14: МАШ.-Ч | G14: 74.1015 | H14: 495524 | I14: 36719072 | J14: 31
A15: ЛРС № 1-1 | B15: Линейная часть | C15: Машины и механизмы | D15: 7 | E15: БУЛЬДОЗЕРЫ ПРИ РАБОТЕ НА ДРУГИХ ВИДАХ СТРОИТЕЛЬСТВА 79 (108) КВТ (Л.С.) | F15: МАШ.-Ч | G15: 59.5094 | H15: 628141.12 | I15: 37380301 | J15: 32
A16: ЛРС № 1-1 | B16: Линейная часть | C16: Машины и механизмы | D16: 8 | E16: БУЛЬДОЗЕРЫ ПРИ РАБОТЕ НА ДРУГИХ ВИДАХ СТРОИТЕЛЬСТВА (КРОМЕ ВОДОХОЗЯЙСТВЕННОГО) 132 (180) КВТ (Л.С.) | F16: МАШ.-Ч | G16: 4.94 | H16: 665973.48 | I16: 3289909 | J16: 33
A17: ЛРС № 1-1 | B17: Линейная часть | C17: Машины и механизмы | D17: 9 | E17: БУЛЬДОЗЕРЫ ПРИ РАБОТЕ НА СООРУЖЕНИИ МАГИСТРАЛЬНЫХ ТРУБОПРОВОДОВ ДО 59 (80) КВТ (Л.С.) | F17: МАШ.-Ч | G17: 1.523 | H17: 628141.12 | I17: 956658.93 | J17: 34
A18: ЛРС № 1-1 | B18: Линейная часть | C18: Машины и механизмы | D18: 10 | E18: БУЛЬДОЗЕРЫ ПРИ РАБОТЕ НА СООРУЖЕНИИ МАГИСТРАЛЬНЫХ ТРУБОПРОВОДОВ 121 (165) КВТ (Л.С.) | F18: МАШ.-Ч | G18: 972.8656 | H18: 665973.48 | I18: 6.4790269e+08 | J18: 35
A19: ЛРС № 1-1 | B19: Линейная часть | C19: Машины и механизмы | D19: 11 | E19: БУЛЬДОЗЕРЫ ПРИ РАБОТЕ НА СООРУЖЕНИИ МАГИСТРАЛЬНЫХ ТРУБОПРОВОДОВ 96 (130) КВТ (Л.С.) | F19: МАШ.-Ч | G19: 491.57264 | H19: 628141.12 | I19: 3.0877699e+08 | J19: 36
A20: ЛРС № 1-1 | B20: Линейная часть | C20: Машины и механизмы | D20: 12 | E20: ГОРЕЛКИ ГАЗОПЛАМЕННЫЕ | F20: МАШ.-Ч | G20: 2300.911 | H20: 25000 | I20: 57522775 | J20: 37
... A155: ЛРС № 1-1 | B155: Линейная часть | C155: Материалы по нормам | D155: 66 | E155: ТРУБЫ СТАЛЬНЫЕ БЕСШОВНЫЕ, ГОРЯЧЕДЕФОРМИРОВАННЫЕ СО СНЯТОЙ ФАСКОЙ ИЗ СТАЛИ МАРОК 15, 20, 25 НАРУЖНЫЙ ДИАМЕТР 325 ММ ТОЛЩИНА СТЕНКИ 8 ММ | F155: М | G155: 187.86 | H155: 800000 | I155: 150288000 | J155: 175
A156: ЛРС № 1-1 | B156: Линейная часть | C156: Материалы по нормам | D156: 67 | E156: ТРУБЫ СТАЛЬНЫЕ ЭЛЕКТРОСВАРНЫЕ КЛАССА ПРОЧНОСТИ К 52 НАРУЖНЫЙ ДИАМЕТР 1020 ММ ТОЛЩИНА СТЕНОК 14,0 ММ | F156: М | G156: 3 | I156: 0 | J156: 176
A157: ЛРС № 1-1 | B157: Линейная часть | C157: Материалы по нормам | D157: 68 | E157: ТРУБЫ СТАЛЬНЫЕ ЭЛЕКТРОСВАРНЫЕ КЛАССА ПРОЧНОСТИ К 52 НАРУЖНЫЙ ДИАМЕТР 1020 ММ ТОЛЩИНА СТЕНОК 14,9 ММ | F157: М | G157: 1.82 | I157: 0 | J157: 177
A158: ЛРС № 1-1 | B158: Линейная часть | C158: Материалы по нормам | D158: 69 | E158: ЗНАКИ ОПОЗНАВАТЕЛЬНЫЕ МЕТАЛЛИЧЕСКИЕ | F158: ШТ | G158: 13.2 | H158: 1200000 | I158: 15840000 | J158: 178
A159: ЛРС № 1-1 | B159: Линейная часть | C159: Материалы по нормам | D159: 71 | E159: ПОРШЕНЬ ОЧИСТИТЕЛЬНЫЙ | F159: ШТ | G159: 0.32439 | H159: 50000 | I159: 16219.5 | J159: 179
A160: ЛРС № 1-1 | B160: Линейная часть | C160: Материалы по нормам | D160: 72 | E160: ПЛИТЫ ФУНДАМЕНТНЫЕ ИЗ БЕТОНА МАРКИ 200, АРМАТУРА 31 КГ/М3, ОБЪЕМОМ 0.2 М3 | F160: М3 | G160: 0.45 | H160: 950000 | I160: 427500 | J160: 180
A161: ЛРС № 1-1 | B161: Линейная часть | C161: Материалы по нормам | D161: 73 | E161: ПЛИТЫ СБОРНЫЕ ЖЕЛЕЗОБЕТОННЫЕ | F161: ШТ | G161: 34.419 | H161: 12000 | I161: 413028 | J161: 181
A162: ЛРС № 1-1 | B162: Линейная часть | C162: Материалы по нормам | D162: 74 | E162: УЗЛЫ ТРУБОПРОВОДОВ ИЗ ТРУБ ДИАМЕТРОМ 45Х4,5 ММ | F162: Т | G162: 0.03 | H162: 23500000 | I162: 705000 | J162: 182
A163: ЛРС № 1-1 | B163: Линейная часть | C163: Материалы по нормам | D163: 75 | E163: УЗЛЫ ТРУБОПРОВОДОВ ИЗ ТРУБ ДИАМЕТРОМ 108Х6 ММ | F163: Т | G163: 0.954 | H163: 23500000 | I163: 22419000 | J163: 183
A164: ЛРС № 1-1 | B164: Линейная часть | C164: Материалы по нормам | D164: 76 | E164: УЗЛЫ ТРУБОПРОВОДОВ ИЗ ТРУБ ДИАМЕТРОМ 325Х10 ММ | F164: Т | G164: 3.924 | H164: 23500000 | I164: 92214000 | J164: 184
A165: ЛРС № 1-1 | B165: Линейная часть | C165: Материалы по нормам | D165: 77 | E165: УЗЛЫ ТРУБОПРОВОДОВ ИЗ ТРУБ ДИАМЕТРОМ 377Х10 ММ | F165: Т | G165: 5.67 | H165: 23500000 | I165: 133245000 | J165: 185
A166: ЛРС № 1-1 | B166: Линейная часть | C166: Материалы по нормам | D166: 78 | E166: КОЛОНКА СВЕЧИ ИЗ ТРУБ ДИАМЕТРОМ 100 ММ | F166: ШТ | G166: 3 | H166: 5200000 | I166: 15600000 | J166: 186
A167: ЛРС № 1-1 | B167: Линейная часть | C167: Материалы по нормам | D167: 79 | E167: ВЕТОШЬ | F167: КГ | G167: 35.664 | H167: 5000 | I167: 178320 | J167: 187
A168: ЛРС № 1-1 | B168: Линейная часть | C168: Материалы по нормам | D168: 80 | E168: ПЕСОК МЕТАЛЛИЧЕСКИЙ | F168: Т | G168: 128.112 | H168: 0 | I168: 0 | J168: 188
A169: ЛРС № 1-1 | B169: Линейная часть | C169: Материалы по нормам | D169: 82 | E169: ПРОПАН-БУТАН, СМЕСЬ ТЕХНИЧЕСКАЯ | F169: КГ | G169: 5191.9596 | H169: 6904.761 | I169: 35849240 | J169: 189
... A179: ЛРС № 1-1 | B179: Линейная часть | C179: Материалы по нормам | D179: 92 | E179: ОТВОДЫ 90 ГРАД. С РАДИУСОМ КРИВИЗНЫ R 1,5ДУ НА РУ МЕНЕЕ ИЛИ 10 МПА (100 КГС/СМ2), ДИАМЕТРОМ УСЛОВНОГО ПРОХОДА 100 ММ, НАРУЖНЫМ ДИАМЕТРОМ 108 ММ, ТОЛЩИНОЙ СТЕНКИ, ММ: 6 | F179: ШТ | G179: 0 | H179: 0 | I179: 0 | J179: 199
A180: ЛРС № 1-1 | B180: Линейная часть | C180: Материалы по нормам | D180: 93 | E180: ОТВОДЫ КРУТОИЗОГНУТЫЕ ШТАМПОВАННЫЕ И ПРОТЯЖНЫЕ НА РУ МЕНЕЕ ИЛИ 10 МПА (100 КГ/СМ2) ИЗ ТРУБ СТАЛЬНЫХ БЕСШОВНЫХ ГОРЯЧЕДЕФОРМИРОВАННЫХ ИЛИ ХОЛОДНОДЕФОРМИРОВАННЫХ ИЗ СТАЛИ 20 ГНУТЫЕ ПОД УГЛОМ 90Ш С РАДИУСОМ КРИВИЗНЫ R 1.5ДУ, ДИАМЕТРОМ УСЛОВНОГО ПРОХОДА 300 ММ, НАРУЖНЫМ ДИАМЕТРОМ 325 ММ, ТОЛЩИНОЙ СТЕНКИ, ММ: 8 | F180: ШТ | G180: 5.4 | I180: 0 | J180: 200
A181: ЛРС № 1-1 | B181: Линейная часть | C181: Материалы по нормам | D181: 94 | E181: ТРОЙНИКИ ШТАМПОВАННЫЕ ИЗ УГЛЕРОДИСТОЙ СТАЛИ НА РУ ДО 16 МПА (160 КГС/СМ2) ИЗ ТРУБ СТАЛЬНЫХ БЕСШОВНЫХ ГОРЯЧЕДЕФОРМИРОВАННЫХ И ХОЛОДНОДЕФОРМИРОВАННЫХ ИЗ СТАЛИ 20 РАВНОПРОХОДНЫЕ, ДИАМЕТРОМ УСЛОВНОГО ПРОХОДА 100 ММ, НАРУЖНЫМ ДИАМЕТРОМ 108 ММ, ТОЛЩИНОЙ СТЕНКИ, ММ: 6 | F181: ШТ | G181: 1.8 | I181: 0 | J181: 201
A182: ЛРС № 1-1 | B182: Линейная часть | C182: Материалы по нормам | D182: 95 | E182: ТРОЙНИКИ ШТАМПОВАННЫЕ ИЗ УГЛЕРОДИСТОЙ СТАЛИ НА РУ ДО 16 МПА (160 КГС/СМ2) ИЗ ТРУБ СТАЛЬНЫХ БЕСШОВНЫХ ГОРЯЧЕДЕФОРМИРОВАННЫХ И ХОЛОДНОДЕФОРМИРОВАННЫХ ИЗ СТАЛИ 20 РАВНОПРОХОДНЫЕ, ДИАМЕТРОМ УСЛОВНОГО ПРОХОДА 300 ММ, НАРУЖНЫМ ДИАМЕТРОМ 325 ММ, ТОЛЩИНОЙ СТЕНКИ, ММ: 8 | F182: ШТ | G182: 4.2 | I182: 0 | J182: 202
A183: ЛРС № 1-1 | B183: Линейная часть | C183: Материалы по нормам | D183: 96 | E183: УЗЛЫ ТРУБОПРОВОДОВ С УСТАНОВКОЙ НЕОБХОДИМЫХ ДЕТАЛЕЙ (ФЛАНЦЕВ, ОТВОДОВ, ТРОЙНИКОВ, ПЕРЕХОДОВ, ЗАГЛУШЕК, ПАТРУБКОВ, П-ОБРАЗНЫХ КОМПЕНСАТОРОВ И Т.П.), ВХОДЯЩИХ В КОНСТРУКЦИЮ ТРУБОПРОВОДА, СО СБОРКОЙ НА ПОСТОЯННЫХ ПРОКЛАДКАХ, КРЕПЛЕНИЕМ БОЛТАМИ И СВАРКОЙ ИЗ ЭЛЕКТРОСВАРНЫХ ТРУБ БОЛЬШОГО ДИАМЕТРА СТ3СП-СТ6СП ДИАМЕТРОМ УСЛОВНОГО ПРОХОДА 1000 ММ, НАРУЖНЫМ ДИАМЕТРОМ 1020 ММ, ТОЛЩИНОЙ СТЕНКИ, ММ: 14 | F183: Т | G183: 12.6752 | I183: 0 | J183: 203
A184: ЛРС № 1-1 | B184: Линейная часть | C184: Материалы по нормам | D184: 97 | E184: КАНАТ ДВОЙНОЙ СВИВКИ, ТИПА ТЛК-О, КОНСТРУКЦИИ 6Х37(1+6+155)+1 О.С. БЕЗ ПОКРЫТИЯ, ИЗ ПРОВОЛОК МАРКИ В, МАРКИРОВОЧНАЯ ГРУППА 1770 Н/ММ2, ДИАМЕТРОМ, ММ: 13,5 | F184: 10М | G184: 9.17 | H184: 1200 | I184: 11004 | J184: 204
...

Sheet Проверка
A1: ПРОВЕРКА ПОЛНОТЫ ПЕРЕНОСА
A2: Сумма по строкам листа «Все ресурсы» сравнивается с итогом раздела в исходной ЛРС.
A4: ЛРС | B4: Раздел | C4: Итог в исходной ЛРС, сум | D4: Сумма перенесённых строк, сум | E4: Расхождение, сум
A5: ЛРС № 1-1 | B5: Машины и механизмы | C5: 3.5422662e+10 | D5: =SUMIFS('Все ресурсы'!$I$5:$I$706,'Все ресурсы'!$A$5:$A$706,A5,'Все ресурсы'!$C$5:$C$706,B5) -> 3.5422662e+10 | E5: =ROUND(D5-C5,0) -> 0
A6: ЛРС № 1-1 | B6: Материалы по нормам | C6: 9.567009e+09 | D6: =SUMIFS('Все ресурсы'!$I$5:$I$706,'Все ресурсы'!$A$5:$A$706,A6,'Все ресурсы'!$C$5:$C$706,B6) -> 9.567009e+09 | E6: =ROUND(D6-C6,0) -> 0
A7: ЛРС № 1-1 | B7: Ресурсы по проекту | C7: 6.9432399e+10 | D7: =SUMIFS('Все ресурсы'!$I$5:$I$706,'Все ресурсы'!$A$5:$A$706,A7,'Все ресурсы'!$C$5:$C$706,B7) -> 6.9432399e+10 | E7: =ROUND(D7-C7,0) -> 0
A8: ЛРС № 1-1 | B8: Оборудование | C8: 4.5573125e+09 | D8: =SUMIFS('Все ресурсы'!$I$5:$I$706,'Все ресурсы'!$A$5:$A$706,A8,'Все ресурсы'!$C$5:$C$706,B8) -> 4.5573125e+09 | E8: =ROUND(D8-C8,0) -> 0
A9: ЛРС № 1-2 | B9: Машины и механизмы | C9: 1.4646239e+08 | D9: =SUMIFS('Все ресурсы'!$I$5:$I$706,'Все ресурсы'!$A$5:$A$706,A9,'Все ресурсы'!$C$5:$C$706,B9) -> 1.4646239e+08 | E9: =ROUND(D9-C9,0) -> 0
A10: ЛРС № 1-2 | B10: Материалы по нормам | C10: 4.2914583e+08 | D10: =SUMIFS('Все ресурсы'!$I$5:$I$706,'Все ресурсы'!$A$5:$A$706,A10,'Все ресурсы'!$C$5:$C$706,B10) -> 4.2914583e+08 | E10: =ROUND(D10-C10,0) -> 0
A11: ЛРС № 1-2 | B11: Ресурсы по проекту | C11: 1.0240274e+08 | D11: =SUMIFS('Все ресурсы'!$I$5:$I$706,'Все ресурсы'!$A$5:$A$706,A11,'Все ресурсы'!$C$5:$C$706,B11) -> 1.0240274e+08 | E11: =ROUND(D11-C11,0) -> 0
A12: ЛРС № 1-2 | B12: Оборудование | C12: 421753760 | D12: =SUMIFS('Все ресурсы'!$I$5:$I$706,'Все ресурсы'!$A$5:$A$706,A12,'Все ресурсы'!$C$5:$C$706,B12) -> 421753760 | E12: =ROUND(D12-C12,0) -> 0
A13: ЛРС № 1-3 | B13: Машины и механизмы | C13: 26725255 | D13: =SUMIFS('Все ресурсы'!$I$5:$I$706,'Все ресурсы'!$A$5:$A$706,A13,'Все ресурсы'!$C$5:$C$706,B13) -> 26725255 | E13: =ROUND(D13-C13,0) -> 0
A14: ЛРС № 1-3 | B14: Материалы по нормам | C14: 19100870 | D14: =SUMIFS('Все ресурсы'!$I$5:$I$706,'Все ресурсы'!$A$5:$A$706,A14,'Все ресурсы'!$C$5:$C$706,B14) -> 19100870 | E14: =ROUND(D14-C14,0) -> 0
A15: ЛРС № 1-3 | B15: Ресурсы по проекту | C15: 1.9296867e+08 | D15: =SUMIFS('Все ресурсы'!$I$5:$I$706,'Все ресурсы'!$A$5:$A$706,A15,'Все ресурсы'!$C$5:$C$706,B15) -> 1.9296867e+08 | E15: =ROUND(D15-C15,0) -> 0
A16: ЛРС № 1-3 | B16: Оборудование | C16: 1100000 | D16: =SUMIFS('Все ресурсы'!$I$5:$I$706,'Все ресурсы'!$A$5:$A$706,A16,'Все ресурсы'!$C$5:$C$706,B16) -> 1100000 | E16: =ROUND(D16-C16,0) -> 0
... A19: ЛРС № 1-4 | B19: Ресурсы по проекту | C19: 2.3620883e+09 | D19: =SUMIFS('Все ресурсы'!$I$5:$I$706,'Все ресурсы'!$A$5:$A$706,A19,'Все ресурсы'!$C$5:$C$706,B19) -> 2.3620883e+09 | E19: =ROUND(D19-C19,0) -> 0
A21: Затраты труда: цена рабочих взята из строки «Итого по трудовым ресурсам» каждой ЛРС (25 287,35 сум/чел-ч); затраты труда машинистов учтены в стоимости маш-ч.
